<sdf version='1.6'>
  <world name='default'>
    <light name='sun' type='directional'>
      <cast_shadows>1</cast_shadows>
      <pose frame=''>0 0 10 0 -0 0</pose>
      <diffuse>0.8 0.8 0.8 1</diffuse>
      <specular>0.2 0.2 0.2 1</specular>
      <attenuation>
        <range>1000</range>
        <constant>0.9</constant>
        <linear>0.01</linear>
        <quadratic>0.001</quadratic>
      </attenuation>
      <direction>-0.5 0.1 -0.9</direction>
    </light>
    <model name='ground_plane'>
      <static>1</static>
      <link name='link'>
        <collision name='collision'>
          <geometry>
            <plane>
              <normal>0 0 1</normal>
              <size>100 100</size>
            </plane>
          </geometry>
          <surface>
            <friction>
              <ode>
                <mu>100</mu>
                <mu2>50</mu2>
              </ode>
              <torsional>
                <ode/>
              </torsional>
            </friction>
            <contact>
              <ode/>
            </contact>
            <bounce/>
          </surface>
          <max_contacts>10</max_contacts>
        </collision>
        <visual name='visual'>
          <cast_shadows>0</cast_shadows>
          <geometry>
            <plane>
              <normal>0 0 1</normal>
              <size>100 100</size>
            </plane>
          </geometry>
          <material>
            <script>
              <uri>file://media/materials/scripts/gazebo.material</uri>
              <name>Gazebo/Grey</name>
            </script>
          </material>
        </visual>
        <self_collide>0</self_collide>
        <enable_wind>0</enable_wind>
        <kinematic>0</kinematic>
      </link>
    </model>
    <gravity>0 0 -9.8</gravity>
    <magnetic_field>6e-06 2.3e-05 -4.2e-05</magnetic_field>
    <atmosphere type='adiabatic'/>
    <physics name='default_physics' default='0' type='ode'>
      <max_step_size>0.001</max_step_size>
      <real_time_factor>1</real_time_factor>
      <real_time_update_rate>1000</real_time_update_rate>
    </physics>
    <scene>
      <ambient>0.4 0.4 0.4 1</ambient>
      <background>0.7 0.7 0.7 1</background>
      <shadows>1</shadows>
    </scene>
    <wind/>
    <spherical_coordinates>
      <surface_model>EARTH_WGS84</surface_model>
      <latitude_deg>0</latitude_deg>
      <longitude_deg>0</longitude_deg>
      <elevation>0</elevation>
      <heading_deg>0</heading_deg>
    </spherical_coordinates>
    <model name='yumi'>
      <link name='yumi_base_link'>
        <pose frame=''>0 0 0.1 0 -0 0</pose>
        <inertial>
          <pose frame=''>1e-06 0 1e-06 0 -0 0</pose>
          <mass>15</mass>
          <inertia>
            <ixx>0.503888</ixx>
            <ixy>-1.94155e-07</ixy>
            <ixz>-8.91205e-06</ixz>
            <iyy>0.600519</iyy>
            <iyz>-1.5607e-07</iyz>
            <izz>0.303893</izz>
          </inertia>
        </inertial>
        <collision name='yumi_base_link_fixed_joint_lump__yumi_body_collision'>
          <pose frame=''>0 0 0 0 -0 0</pose>
          <geometry>
            <mesh>
              <scale>1 1 1</scale>
              <uri>/home/houlam/yumi_depends_ws/src/yumi/yumi_description/meshes/coarse/body.stl</uri>
            </mesh>
          </geometry>
          <surface>
            <contact>
              <ode/>
            </contact>
            <friction>
              <ode>
                <mu>0.2</mu>
                <mu2>0.2</mu2>
              </ode>
              <torsional>
                <ode/>
              </torsional>
            </friction>
            <bounce/>
          </surface>
          <max_contacts>10</max_contacts>
        </collision>
        <collision name='yumi_base_link_fixed_joint_lump__camera_link_collision_1'>
          <pose frame=''>1.10946 0 0.891829 -3.14159 0.858407 -3.14159</pose>
          <geometry>
            <box>
              <size>0.02505 0.09 0.025</size>
            </box>
          </geometry>
          <surface>
            <contact>
              <ode>
                <kp>1e+13</kp>
                <kd>1</kd>
              </ode>
            </contact>
            <friction>
              <ode>
                <mu2>1</mu2>
                <fdir1>0 0 0</fdir1>
              </ode>
              <torsional>
                <ode/>
              </torsional>
            </friction>
            <bounce/>
          </surface>
          <max_contacts>10</max_contacts>
        </collision>
        <visual name='yumi_base_link_fixed_joint_lump__yumi_body_visual'>
          <pose frame=''>0 0 0 0 -0 0</pose>
          <geometry>
            <mesh>
              <scale>1 1 1</scale>
              <uri>/home/houlam/yumi_depends_ws/src/yumi/yumi_description/meshes/body.stl</uri>
            </mesh>
          </geometry>
          <material>
            <script>
              <name>Gazebo/Ivory</name>
              <uri>file://media/materials/scripts/gazebo.material</uri>
            </script>
          </material>
        </visual>
        <visual name='yumi_base_link_fixed_joint_lump__camera_link_visual_1'>
          <pose frame=''>1.09972 0 0.880553 -2.4292 -0 1.5708</pose>
          <geometry>
            <mesh>
              <scale>1 1 1</scale>
              <uri>/home/houlam/yumi_depends_ws/src/realsense2_description/meshes/d435.dae</uri>
            </mesh>
          </geometry>
          <material>
            <script>
              <uri>__default__</uri>
              <name>__default__</name>
            </script>
          </material>
        </visual>
        <velocity_decay/>
        <gravity>1</gravity>
        <velocity_decay/>
        <self_collide>0</self_collide>
        <enable_wind>0</enable_wind>
        <kinematic>0</kinematic>
        <gravity>1</gravity>
        <sensor name='cameracolor' type='camera'>
          <camera name='camera'>
            <horizontal_fov>1.21126</horizontal_fov>
            <image>
              <width>640</width>
              <height>480</height>
              <format>RGB_INT8</format>
            </image>
            <clip>
              <near>0.1</near>
              <far>100</far>
            </clip>
            <noise>
              <type>gaussian</type>
              <mean>0</mean>
              <stddev>0.007</stddev>
            </noise>
          </camera>
          <always_on>1</always_on>
          <update_rate>30</update_rate>
          <visualize>1</visualize>
          <pose frame=''>1.10946 0.0175 0.891829 -3.14159 0.858407 -3.14159</pose>
        </sensor>
        <sensor name='cameraired1' type='camera'>
          <camera name='camera'>
            <horizontal_fov>1.48702</horizontal_fov>
            <image>
              <width>1280</width>
              <height>720</height>
              <format>L_INT8</format>
            </image>
            <clip>
              <near>0.1</near>
              <far>100</far>
            </clip>
            <noise>
              <type>gaussian</type>
              <mean>0</mean>
              <stddev>0.05</stddev>
            </noise>
          </camera>
          <always_on>1</always_on>
          <update_rate>90</update_rate>
          <visualize>0</visualize>
          <pose frame=''>1.10946 0.0175 0.891829 -3.14159 0.858407 -3.14159</pose>
        </sensor>
        <sensor name='cameraired2' type='camera'>
          <camera name='camera'>
            <horizontal_fov>1.48702</horizontal_fov>
            <image>
              <width>1280</width>
              <height>720</height>
              <format>L_INT8</format>
            </image>
            <clip>
              <near>0.1</near>
              <far>100</far>
            </clip>
            <noise>
              <type>gaussian</type>
              <mean>0</mean>
              <stddev>0.05</stddev>
            </noise>
          </camera>
          <always_on>1</always_on>
          <update_rate>90</update_rate>
          <visualize>0</visualize>
          <pose frame=''>1.10946 0.0175 0.891829 -3.14159 0.858407 -3.14159</pose>
        </sensor>
        <sensor name='cameradepth' type='depth'>
          <camera name='camera'>
            <horizontal_fov>1.48702</horizontal_fov>
            <image>
              <width>1280</width>
              <height>720</height>
            </image>
            <clip>
              <near>0.1</near>
              <far>100</far>
            </clip>
            <noise>
              <type>gaussian</type>
              <mean>0</mean>
              <stddev>0.1</stddev>
            </noise>
          </camera>
          <always_on>1</always_on>
          <update_rate>90</update_rate>
          <visualize>0</visualize>
          <pose frame=''>1.10946 0.0175 0.891829 -3.14159 0.858407 -3.14159</pose>
        </sensor>
      </link>
      <joint name='world_joint' type='fixed'>
        <child>yumi_base_link</child>
        <parent>world</parent>
      </joint>
      <link name='yumi_link_1_l'>
        <pose frame=''>0.05355 0.0725 0.51492 0.9781 -0.5716 2.318</pose>
        <inertial>
          <pose frame=''>0 -0.03 0.12 0 -0 0</pose>
          <mass>2</mass>
          <inertia>
            <ixx>0.1</ixx>
            <ixy>0</ixy>
            <ixz>0</ixz>
            <iyy>0.1</iyy>
            <iyz>0</iyz>
            <izz>0.1</izz>
          </inertia>
        </inertial>
        <collision name='yumi_link_1_l_collision'>
          <pose frame=''>0 0 0 0 -0 0</pose>
          <geometry>
            <mesh>
              <scale>1 1 1</scale>
              <uri>/home/houlam/yumi_depends_ws/src/yumi/yumi_description/meshes/coarse/link_1.stl</uri>
            </mesh>
          </geometry>
          <max_contacts>10</max_contacts>
          <surface>
            <contact>
              <ode/>
            </contact>
            <bounce/>
            <friction>
              <torsional>
                <ode/>
              </torsional>
              <ode/>
            </friction>
          </surface>
        </collision>
        <visual name='yumi_link_1_l_visual'>
          <pose frame=''>0 0 0 0 -0 0</pose>
          <geometry>
            <mesh>
              <scale>1 1 1</scale>
              <uri>/home/houlam/yumi_depends_ws/src/yumi/yumi_description/meshes/link_1.stl</uri>
            </mesh>
          </geometry>
        </visual>
        <self_collide>0</self_collide>
        <enable_wind>0</enable_wind>
        <kinematic>0</kinematic>
      </link>
      <joint name='yumi_joint_1_l' type='revolute'>
        <child>yumi_link_1_l</child>
        <parent>yumi_base_link</parent>
        <axis>
          <xyz>0.813834 0.341993 0.469803</xyz>
          <limit>
            <lower>-2.94088</lower>
            <upper>2.94088</upper>
            <effort>300</effort>
            <velocity>3.14159</velocity>
          </limit>
          <dynamics>
            <damping>0.5</damping>
            <friction>0</friction>
            <spring_reference>0</spring_reference>
            <spring_stiffness>0</spring_stiffness>
          </dynamics>
          <use_parent_model_frame>1</use_parent_model_frame>
        </axis>
      </joint>
      <link name='yumi_link_2_l'>
        <pose frame=''>0.117787 0.125209 0.57813 2.5489 -0.5716 2.318</pose>
        <inertial>
          <pose frame=''>0 0 0 0 -0 0</pose>
          <mass>2</mass>
          <inertia>
            <ixx>0.1</ixx>
            <ixy>0</ixy>
            <ixz>0</ixz>
            <iyy>0.1</iyy>
            <iyz>0</iyz>
            <izz>0.1</izz>
          </inertia>
        </inertial>
        <collision name='yumi_link_2_l_collision'>
          <pose frame=''>0 0 0 0 -0 0</pose>
          <geometry>
            <mesh>
              <scale>1 1 1</scale>
              <uri>/home/houlam/yumi_depends_ws/src/yumi/yumi_description/meshes/coarse/link_2.stl</uri>
            </mesh>
          </geometry>
          <max_contacts>10</max_contacts>
          <surface>
            <contact>
              <ode/>
            </contact>
            <bounce/>
            <friction>
              <torsional>
                <ode/>
              </torsional>
              <ode/>
            </friction>
          </surface>
        </collision>
        <visual name='yumi_link_2_l_visual'>
          <pose frame=''>0 0 0 0 -0 0</pose>
          <geometry>
            <mesh>
              <scale>1 1 1</scale>
              <uri>/home/houlam/yumi_depends_ws/src/yumi/yumi_description/meshes/link_2.stl</uri>
            </mesh>
          </geometry>
        </visual>
        <self_collide>0</self_collide>
        <enable_wind>0</enable_wind>
        <kinematic>0</kinematic>
      </link>
      <joint name='yumi_joint_2_l' type='revolute'>
        <child>yumi_link_2_l</child>
        <parent>yumi_link_1_l</parent>
        <axis>
          <xyz>0.104847 0.708787 -0.697587</xyz>
          <limit>
            <lower>-2.50455</lower>
            <upper>0.759218</upper>
            <effort>300</effort>
            <velocity>3.14159</velocity>
          </limit>
          <dynamics>
            <damping>0.5</damping>
            <friction>0</friction>
            <spring_reference>0</spring_reference>
            <spring_stiffness>0</spring_stiffness>
          </dynamics>
          <use_parent_model_frame>1</use_parent_model_frame>
        </axis>
      </joint>
      <link name='yumi_link_3_l'>
        <pose frame=''>0.275588 0.165806 0.643096 0.9781 -0.5716 2.318</pose>
        <inertial>
          <pose frame=''>0 0 0 0 -0 0</pose>
          <mass>2</mass>
          <inertia>
            <ixx>0.1</ixx>
            <ixy>0</ixy>
            <ixz>0</ixz>
            <iyy>0.1</iyy>
            <iyz>0</iyz>
            <izz>0.1</izz>
          </inertia>
        </inertial>
        <collision name='yumi_link_3_l_collision'>
          <pose frame=''>0 0 0 0 -0 0</pose>
          <geometry>
            <mesh>
              <scale>1 1 1</scale>
              <uri>/home/houlam/yumi_depends_ws/src/yumi/yumi_description/meshes/coarse/link_3.stl</uri>
            </mesh>
          </geometry>
          <max_contacts>10</max_contacts>
          <surface>
            <contact>
              <ode/>
            </contact>
            <bounce/>
            <friction>
              <torsional>
                <ode/>
              </torsional>
              <ode/>
            </friction>
          </surface>
        </collision>
        <visual name='yumi_link_3_l_visual'>
          <pose frame=''>0 0 0 0 -0 0</pose>
          <geometry>
            <mesh>
              <scale>1 1 1</scale>
              <uri>/home/houlam/yumi_depends_ws/src/yumi/yumi_description/meshes/link_3.stl</uri>
            </mesh>
          </geometry>
        </visual>
        <self_collide>0</self_collide>
        <enable_wind>0</enable_wind>
        <kinematic>0</kinematic>
      </link>
      <joint name='yumi_joint_7_l' type='revolute'>
        <child>yumi_link_3_l</child>
        <parent>yumi_link_2_l</parent>
        <axis>
          <xyz>0.813834 0.341993 0.469803</xyz>
          <limit>
            <lower>-2.94088</lower>
            <upper>2.94088</upper>
            <effort>300</effort>
            <velocity>3.14159</velocity>
          </limit>
          <dynamics>
            <damping>0.5</damping>
            <friction>0</friction>
            <spring_reference>0</spring_reference>
            <spring_stiffness>0</spring_stiffness>
          </dynamics>
          <use_parent_model_frame>1</use_parent_model_frame>
        </axis>
      </joint>
      <link name='yumi_link_4_l'>
        <pose frame=''>0.363599 0.166892 0.657428 -2.48197 -0.489067 0.397819</pose>
        <inertial>
          <pose frame=''>0 0 0 0 -0 0</pose>
          <mass>2</mass>
          <inertia>
            <ixx>0.1</ixx>
            <ixy>0</ixy>
            <ixz>0</ixz>
            <iyy>0.1</iyy>
            <iyz>0</iyz>
            <izz>0.1</izz>
          </inertia>
        </inertial>
        <collision name='yumi_link_4_l_collision'>
          <pose frame=''>0 0 0 0 -0 0</pose>
          <geometry>
            <mesh>
              <scale>1 1 1</scale>
              <uri>/home/houlam/yumi_depends_ws/src/yumi/yumi_description/meshes/coarse/link_4.stl</uri>
            </mesh>
          </geometry>
          <max_contacts>10</max_contacts>
          <surface>
            <contact>
              <ode/>
            </contact>
            <bounce/>
            <friction>
              <torsional>
                <ode/>
              </torsional>
              <ode/>
            </friction>
          </surface>
        </collision>
        <visual name='yumi_link_4_l_visual'>
          <pose frame=''>0 0 0 0 -0 0</pose>
          <geometry>
            <mesh>
              <scale>1 1 1</scale>
              <uri>/home/houlam/yumi_depends_ws/src/yumi/yumi_description/meshes/link_4.stl</uri>
            </mesh>
          </geometry>
        </visual>
        <self_collide>0</self_collide>
        <enable_wind>0</enable_wind>
        <kinematic>0</kinematic>
      </link>
      <joint name='yumi_joint_3_l' type='revolute'>
        <child>yumi_link_4_l</child>
        <parent>yumi_link_3_l</parent>
        <axis>
          <xyz>0.104847 0.708787 -0.697587</xyz>
          <limit>
            <lower>-2.15548</lower>
            <upper>1.39626</upper>
            <effort>300</effort>
            <velocity>3.14159</velocity>
          </limit>
          <dynamics>
            <damping>0.5</damping>
            <friction>0</friction>
            <spring_reference>0</spring_reference>
            <spring_stiffness>0</spring_stiffness>
          </dynamics>
          <use_parent_model_frame>1</use_parent_model_frame>
        </axis>
      </joint>
      <link name='yumi_link_5_l'>
        <pose frame=''>0.490643 0.079182 0.587404 2.23042 -0.489067 0.397819</pose>
        <inertial>
          <pose frame=''>0 0 0 0 -0 0</pose>
          <mass>2</mass>
          <inertia>
            <ixx>0.1</ixx>
            <ixy>0</ixy>
            <ixz>0</ixz>
            <iyy>0.1</iyy>
            <iyz>0</iyz>
            <izz>0.1</izz>
          </inertia>
        </inertial>
        <collision name='yumi_link_5_l_collision'>
          <pose frame=''>0 0 0 0 -0 0</pose>
          <geometry>
            <mesh>
              <scale>1 1 1</scale>
              <uri>/home/houlam/yumi_depends_ws/src/yumi/yumi_description/meshes/coarse/link_5.stl</uri>
            </mesh>
          </geometry>
          <max_contacts>10</max_contacts>
          <surface>
            <contact>
              <ode/>
            </contact>
            <bounce/>
            <friction>
              <torsional>
                <ode/>
              </torsional>
              <ode/>
            </friction>
          </surface>
        </collision>
        <visual name='yumi_link_5_l_visual'>
          <pose frame=''>0 0 0 0 -0 0</pose>
          <geometry>
            <mesh>
              <scale>1 1 1</scale>
              <uri>/home/houlam/yumi_depends_ws/src/yumi/yumi_description/meshes/link_5.stl</uri>
            </mesh>
          </geometry>
        </visual>
        <self_collide>0</self_collide>
        <enable_wind>0</enable_wind>
        <kinematic>0</kinematic>
      </link>
      <joint name='yumi_joint_4_l' type='revolute'>
        <child>yumi_link_5_l</child>
        <parent>yumi_link_4_l</parent>
        <axis>
          <xyz>0.57156 -0.616978 -0.540978</xyz>
          <limit>
            <lower>-5.06145</lower>
            <upper>5.06145</upper>
            <effort>300</effort>
            <velocity>6.98132</velocity>
          </limit>
          <dynamics>
            <damping>0.5</damping>
            <friction>0</friction>
            <spring_reference>0</spring_reference>
            <spring_stiffness>0</spring_stiffness>
          </dynamics>
          <use_parent_model_frame>1</use_parent_model_frame>
        </axis>
      </joint>
      <link name='yumi_link_6_l'>
        <pose frame=''>0.526049 0.00801 0.520411 -2.48197 -0.489067 0.397819</pose>
        <inertial>
          <pose frame=''>0 0 0 0 -0 0</pose>
          <mass>2</mass>
          <inertia>
            <ixx>0.1</ixx>
            <ixy>0</ixy>
            <ixz>0</ixz>
            <iyy>0.1</iyy>
            <iyz>0</iyz>
            <izz>0.1</izz>
          </inertia>
        </inertial>
        <collision name='yumi_link_6_l_collision'>
          <pose frame=''>0 0 0 0 -0 0</pose>
          <geometry>
            <mesh>
              <scale>1 1 1</scale>
              <uri>/home/houlam/yumi_depends_ws/src/yumi/yumi_description/meshes/coarse/link_6.stl</uri>
            </mesh>
          </geometry>
          <max_contacts>10</max_contacts>
          <surface>
            <contact>
              <ode/>
            </contact>
            <bounce/>
            <friction>
              <torsional>
                <ode/>
              </torsional>
              <ode/>
            </friction>
          </surface>
        </collision>
        <visual name='yumi_link_6_l_visual'>
          <pose frame=''>0 0 0 0 -0 0</pose>
          <geometry>
            <mesh>
              <scale>1 1 1</scale>
              <uri>/home/houlam/yumi_depends_ws/src/yumi/yumi_description/meshes/link_6.stl</uri>
            </mesh>
          </geometry>
        </visual>
        <self_collide>0</self_collide>
        <enable_wind>0</enable_wind>
        <kinematic>0</kinematic>
      </link>
      <joint name='yumi_joint_5_l' type='revolute'>
        <child>yumi_link_6_l</child>
        <parent>yumi_link_5_l</parent>
        <axis>
          <xyz>0.104847 0.708787 -0.697587</xyz>
          <limit>
            <lower>-1.53589</lower>
            <upper>2.40855</upper>
            <effort>300</effort>
            <velocity>6.98132</velocity>
          </limit>
          <dynamics>
            <damping>0.5</damping>
            <friction>0</friction>
            <spring_reference>0</spring_reference>
            <spring_stiffness>0</spring_stiffness>
          </dynamics>
          <use_parent_model_frame>1</use_parent_model_frame>
        </axis>
      </joint>
      <link name='yumi_link_7_l'>
        <pose frame=''>0.564597 -0.000649 0.517407 2.23042 -0.489067 0.397819</pose>
        <inertial>
          <pose frame=''>0 0 0.000636 0 -0 0</pose>
          <mass>2.2</mass>
          <inertia>
            <ixx>0.100109</ixx>
            <ixy>0</ixy>
            <ixz>0</ixz>
            <iyy>0.100109</iyy>
            <iyz>0</iyz>
            <izz>0.1001</izz>
          </inertia>
        </inertial>
        <collision name='yumi_link_7_l_collision'>
          <pose frame=''>0 0 0 0 -0 0</pose>
          <geometry>
            <mesh>
              <scale>1 1 1</scale>
              <uri>/home/houlam/yumi_depends_ws/src/yumi/yumi_description/meshes/coarse/link_7.stl</uri>
            </mesh>
          </geometry>
          <max_contacts>10</max_contacts>
          <surface>
            <contact>
              <ode/>
            </contact>
            <bounce/>
            <friction>
              <torsional>
                <ode/>
              </torsional>
              <ode/>
            </friction>
          </surface>
        </collision>
        <collision name='yumi_link_7_l_fixed_joint_lump__gripper_l_base_collision_1'>
          <pose frame=''>0 0 0.007 0 -0 -3.14159</pose>
          <geometry>
            <mesh>
              <scale>1 1 1</scale>
              <uri>/home/houlam/yumi_depends_ws/src/yumi/yumi_description/meshes/gripper/coarse/base.stl</uri>
            </mesh>
          </geometry>
          <surface>
            <contact>
              <ode/>
            </contact>
            <friction>
              <ode>
                <mu>0.2</mu>
                <mu2>0.2</mu2>
              </ode>
              <torsional>
                <ode/>
              </torsional>
            </friction>
            <bounce/>
          </surface>
          <max_contacts>10</max_contacts>
        </collision>
        <visual name='yumi_link_7_l_visual'>
          <pose frame=''>0 0 0 0 -0 0</pose>
          <geometry>
            <mesh>
              <scale>1 1 1</scale>
              <uri>/home/houlam/yumi_depends_ws/src/yumi/yumi_description/meshes/link_7.stl</uri>
            </mesh>
          </geometry>
        </visual>
        <visual name='yumi_link_7_l_fixed_joint_lump__gripper_l_base_visual_1'>
          <pose frame=''>0 0 0.007 0 -0 -3.14159</pose>
          <geometry>
            <mesh>
              <scale>1 1 1</scale>
              <uri>/home/houlam/yumi_depends_ws/src/yumi/yumi_description/meshes/gripper/base.stl</uri>
            </mesh>
          </geometry>
          <material>
            <script>
              <name>Gazebo/Light_Grey</name>
              <uri>file://media/materials/scripts/gazebo.material</uri>
            </script>
          </material>
        </visual>
        <gravity>1</gravity>
        <velocity_decay/>
        <self_collide>0</self_collide>
        <enable_wind>0</enable_wind>
        <kinematic>0</kinematic>
      </link>
      <joint name='yumi_joint_6_l' type='revolute'>
        <child>yumi_link_7_l</child>
        <parent>yumi_link_6_l</parent>
        <axis>
          <xyz>0.57156 -0.616978 -0.540978</xyz>
          <limit>
            <lower>-3.9968</lower>
            <upper>3.9968</upper>
            <effort>300</effort>
            <velocity>6.98132</velocity>
          </limit>
          <dynamics>
            <damping>0.5</damping>
            <friction>0</friction>
            <spring_reference>0</spring_reference>
            <spring_stiffness>0</spring_stiffness>
          </dynamics>
          <use_parent_model_frame>1</use_parent_model_frame>
        </axis>
      </joint>
      <link name='gripper_l_finger_r'>
        <pose frame=''>0.615756 -0.061216 0.472875 -2.23042 0.489067 -2.74377</pose>
        <inertial>
          <pose frame=''>0 0 0 0 -0 0</pose>
          <mass>0.04</mass>
          <inertia>
            <ixx>1.66667e-05</ixx>
            <ixy>0</ixy>
            <ixz>0</ixz>
            <iyy>1.66667e-05</iyy>
            <iyz>0</iyz>
            <izz>1.66667e-05</izz>
          </inertia>
        </inertial>
        <collision name='gripper_l_finger_r_collision'>
          <pose frame=''>0 0 0 0 -0 0</pose>
          <geometry>
            <mesh>
              <scale>1 1 1</scale>
              <uri>/home/houlam/yumi_depends_ws/src/yumi/yumi_description/meshes/gripper/coarse/finger.stl</uri>
            </mesh>
          </geometry>
          <max_contacts>10</max_contacts>
          <surface>
            <contact>
              <ode/>
            </contact>
            <bounce/>
            <friction>
              <torsional>
                <ode/>
              </torsional>
              <ode/>
            </friction>
          </surface>
        </collision>
        <visual name='gripper_l_finger_r_visual'>
          <pose frame=''>0 0 0 0 -0 0</pose>
          <geometry>
            <mesh>
              <scale>1 1 1</scale>
              <uri>/home/houlam/yumi_depends_ws/src/yumi/yumi_description/meshes/gripper/finger.stl</uri>
            </mesh>
          </geometry>
        </visual>
        <self_collide>0</self_collide>
        <enable_wind>0</enable_wind>
        <kinematic>0</kinematic>
      </link>
      <joint name='gripper_l_joint' type='prismatic'>
        <child>gripper_l_finger_r</child>
        <parent>yumi_link_7_l</parent>
        <axis>
          <xyz>0.813834 0.341993 0.469803</xyz>
          <limit>
            <lower>0</lower>
            <upper>0.025</upper>
            <effort>20</effort>
            <velocity>2</velocity>
          </limit>
          <dynamics>
            <damping>1</damping>
            <friction>0</friction>
            <spring_reference>0</spring_reference>
            <spring_stiffness>0</spring_stiffness>
          </dynamics>
          <use_parent_model_frame>1</use_parent_model_frame>
        </axis>
      </joint>
      <link name='gripper_l_finger_l'>
        <pose frame=''>0.617119 -0.052001 0.463806 2.23042 -0.489067 0.397819</pose>
        <inertial>
          <pose frame=''>0 0 0 0 -0 0</pose>
          <mass>0.04</mass>
          <inertia>
            <ixx>1.66667e-05</ixx>
            <ixy>0</ixy>
            <ixz>0</ixz>
            <iyy>1.66667e-05</iyy>
            <iyz>0</iyz>
            <izz>1.66667e-05</izz>
          </inertia>
        </inertial>
        <collision name='gripper_l_finger_l_collision'>
          <pose frame=''>0 0 0 0 -0 0</pose>
          <geometry>
            <mesh>
              <scale>1 1 1</scale>
              <uri>/home/houlam/yumi_depends_ws/src/yumi/yumi_description/meshes/gripper/coarse/finger.stl</uri>
            </mesh>
          </geometry>
          <max_contacts>10</max_contacts>
          <surface>
            <contact>
              <ode/>
            </contact>
            <bounce/>
            <friction>
              <torsional>
                <ode/>
              </torsional>
              <ode/>
            </friction>
          </surface>
        </collision>
        <visual name='gripper_l_finger_l_visual'>
          <pose frame=''>0 0 0 0 -0 0</pose>
          <geometry>
            <mesh>
              <scale>1 1 1</scale>
              <uri>/home/houlam/yumi_depends_ws/src/yumi/yumi_description/meshes/gripper/finger.stl</uri>
            </mesh>
          </geometry>
        </visual>
        <self_collide>0</self_collide>
        <enable_wind>0</enable_wind>
        <kinematic>0</kinematic>
      </link>
      <joint name='gripper_l_joint_m' type='prismatic'>
        <child>gripper_l_finger_l</child>
        <parent>yumi_link_7_l</parent>
        <axis>
          <xyz>-0.813834 -0.341993 -0.469803</xyz>
          <limit>
            <lower>0</lower>
            <upper>0.025</upper>
            <effort>20</effort>
            <velocity>2</velocity>
          </limit>
          <dynamics>
            <damping>1</damping>
            <friction>0</friction>
            <spring_reference>0</spring_reference>
            <spring_stiffness>0</spring_stiffness>
          </dynamics>
          <use_parent_model_frame>1</use_parent_model_frame>
        </axis>
      </joint>
      <link name='yumi_link_1_r'>
        <pose frame=''>0.05355 -0.0725 0.51492 -0.9795 -0.5682 -2.3155</pose>
        <inertial>
          <pose frame=''>0 -0.03 0.12 0 -0 0</pose>
          <mass>2</mass>
          <inertia>
            <ixx>0.1</ixx>
            <ixy>0</ixy>
            <ixz>0</ixz>
            <iyy>0.1</iyy>
            <iyz>0</iyz>
            <izz>0.1</izz>
          </inertia>
        </inertial>
        <collision name='yumi_link_1_r_collision'>
          <pose frame=''>0 0 0 0 -0 0</pose>
          <geometry>
            <mesh>
              <scale>1 1 1</scale>
              <uri>/home/houlam/yumi_depends_ws/src/yumi/yumi_description/meshes/coarse/link_1.stl</uri>
            </mesh>
          </geometry>
          <max_contacts>10</max_contacts>
          <surface>
            <contact>
              <ode/>
            </contact>
            <bounce/>
            <friction>
              <torsional>
                <ode/>
              </torsional>
              <ode/>
            </friction>
          </surface>
        </collision>
        <visual name='yumi_link_1_r_visual'>
          <pose frame=''>0 0 0 0 -0 0</pose>
          <geometry>
            <mesh>
              <scale>1 1 1</scale>
              <uri>/home/houlam/yumi_depends_ws/src/yumi/yumi_description/meshes/link_1.stl</uri>
            </mesh>
          </geometry>
        </visual>
        <self_collide>0</self_collide>
        <enable_wind>0</enable_wind>
        <kinematic>0</kinematic>
      </link>
      <joint name='yumi_joint_1_r' type='revolute'>
        <child>yumi_link_1_r</child>
        <parent>yumi_base_link</parent>
        <axis>
          <xyz>0.813754 -0.342122 0.469848</xyz>
          <limit>
            <lower>-2.94088</lower>
            <upper>2.94088</upper>
            <effort>300</effort>
            <velocity>3.14159</velocity>
          </limit>
          <dynamics>
            <damping>0.5</damping>
            <friction>0</friction>
            <spring_reference>0</spring_reference>
            <spring_stiffness>0</spring_stiffness>
          </dynamics>
          <use_parent_model_frame>1</use_parent_model_frame>
        </axis>
      </joint>
      <link name='yumi_link_2_r'>
        <pose frame=''>0.117788 -0.125305 0.578048 0.591296 -0.5682 -2.3155</pose>
        <inertial>
          <pose frame=''>0 0 0 0 -0 0</pose>
          <mass>2</mass>
          <inertia>
            <ixx>0.1</ixx>
            <ixy>0</ixy>
            <ixz>0</ixz>
            <iyy>0.1</iyy>
            <iyz>0</iyz>
            <izz>0.1</izz>
          </inertia>
        </inertial>
        <collision name='yumi_link_2_r_collision'>
          <pose frame=''>0 0 0 0 -0 0</pose>
          <geometry>
            <mesh>
              <scale>1 1 1</scale>
              <uri>/home/houlam/yumi_depends_ws/src/yumi/yumi_description/meshes/coarse/link_2.stl</uri>
            </mesh>
          </geometry>
          <max_contacts>10</max_contacts>
          <surface>
            <contact>
              <ode/>
            </contact>
            <bounce/>
            <friction>
              <torsional>
                <ode/>
              </torsional>
              <ode/>
            </friction>
          </surface>
        </collision>
        <visual name='yumi_link_2_r_visual'>
          <pose frame=''>0 0 0 0 -0 0</pose>
          <geometry>
            <mesh>
              <scale>1 1 1</scale>
              <uri>/home/houlam/yumi_depends_ws/src/yumi/yumi_description/meshes/link_2.stl</uri>
            </mesh>
          </geometry>
        </visual>
        <self_collide>0</self_collide>
        <enable_wind>0</enable_wind>
        <kinematic>0</kinematic>
      </link>
      <joint name='yumi_joint_2_r' type='revolute'>
        <child>yumi_link_2_r</child>
        <parent>yumi_link_1_r</parent>
        <axis>
          <xyz>-0.107089 0.706299 0.699767</xyz>
          <limit>
            <lower>-2.50455</lower>
            <upper>0.759218</upper>
            <effort>300</effort>
            <velocity>3.14159</velocity>
          </limit>
          <dynamics>
            <damping>0.5</damping>
            <friction>0</friction>
            <spring_reference>0</spring_reference>
            <spring_stiffness>0</spring_stiffness>
          </dynamics>
          <use_parent_model_frame>1</use_parent_model_frame>
        </axis>
      </joint>
      <link name='yumi_link_3_r'>
        <pose frame=''>0.275566 -0.165841 0.643109 -0.9795 -0.5682 -2.3155</pose>
        <inertial>
          <pose frame=''>0 0 0 0 -0 0</pose>
          <mass>2</mass>
          <inertia>
            <ixx>0.1</ixx>
            <ixy>0</ixy>
            <ixz>0</ixz>
            <iyy>0.1</iyy>
            <iyz>0</iyz>
            <izz>0.1</izz>
          </inertia>
        </inertial>
        <collision name='yumi_link_3_r_collision'>
          <pose frame=''>0 0 0 0 -0 0</pose>
          <geometry>
            <mesh>
              <scale>1 1 1</scale>
              <uri>/home/houlam/yumi_depends_ws/src/yumi/yumi_description/meshes/coarse/link_3.stl</uri>
            </mesh>
          </geometry>
          <max_contacts>10</max_contacts>
          <surface>
            <contact>
              <ode/>
            </contact>
            <bounce/>
            <friction>
              <torsional>
                <ode/>
              </torsional>
              <ode/>
            </friction>
          </surface>
        </collision>
        <visual name='yumi_link_3_r_visual'>
          <pose frame=''>0 0 0 0 -0 0</pose>
          <geometry>
            <mesh>
              <scale>1 1 1</scale>
              <uri>/home/houlam/yumi_depends_ws/src/yumi/yumi_description/meshes/link_3.stl</uri>
            </mesh>
          </geometry>
        </visual>
        <self_collide>0</self_collide>
        <enable_wind>0</enable_wind>
        <kinematic>0</kinematic>
      </link>
      <joint name='yumi_joint_7_r' type='revolute'>
        <child>yumi_link_3_r</child>
        <parent>yumi_link_2_r</parent>
        <axis>
          <xyz>0.813754 -0.342122 0.469848</xyz>
          <limit>
            <lower>-2.94088</lower>
            <upper>2.94088</upper>
            <effort>300</effort>
            <velocity>3.14159</velocity>
          </limit>
          <dynamics>
            <damping>0.5</damping>
            <friction>0</friction>
            <spring_reference>0</spring_reference>
            <spring_stiffness>0</spring_stiffness>
          </dynamics>
          <use_parent_model_frame>1</use_parent_model_frame>
        </axis>
      </joint>
      <link name='yumi_link_4_r'>
        <pose frame=''>0.363558 -0.166821 0.657563 -0.655546 -0.489119 -0.397989</pose>
        <inertial>
          <pose frame=''>0 0 0 0 -0 0</pose>
          <mass>2</mass>
          <inertia>
            <ixx>0.1</ixx>
            <ixy>0</ixy>
            <ixz>0</ixz>
            <iyy>0.1</iyy>
            <iyz>0</iyz>
            <izz>0.1</izz>
          </inertia>
        </inertial>
        <collision name='yumi_link_4_r_collision'>
          <pose frame=''>0 0 0 0 -0 0</pose>
          <geometry>
            <mesh>
              <scale>1 1 1</scale>
              <uri>/home/houlam/yumi_depends_ws/src/yumi/yumi_description/meshes/coarse/link_4.stl</uri>
            </mesh>
          </geometry>
          <max_contacts>10</max_contacts>
          <surface>
            <contact>
              <ode/>
            </contact>
            <bounce/>
            <friction>
              <torsional>
                <ode/>
              </torsional>
              <ode/>
            </friction>
          </surface>
        </collision>
        <visual name='yumi_link_4_r_visual'>
          <pose frame=''>0 0 0 0 -0 0</pose>
          <geometry>
            <mesh>
              <scale>1 1 1</scale>
              <uri>/home/houlam/yumi_depends_ws/src/yumi/yumi_description/meshes/link_4.stl</uri>
            </mesh>
          </geometry>
        </visual>
        <self_collide>0</self_collide>
        <enable_wind>0</enable_wind>
        <kinematic>0</kinematic>
      </link>
      <joint name='yumi_joint_3_r' type='revolute'>
        <child>yumi_link_4_r</child>
        <parent>yumi_link_3_r</parent>
        <axis>
          <xyz>-0.107089 0.706299 0.699767</xyz>
          <limit>
            <lower>-2.15548</lower>
            <upper>1.39626</upper>
            <effort>300</effort>
            <velocity>3.14159</velocity>
          </limit>
          <dynamics>
            <damping>0.5</damping>
            <friction>0</friction>
            <spring_reference>0</spring_reference>
            <spring_stiffness>0</spring_stiffness>
          </dynamics>
          <use_parent_model_frame>1</use_parent_model_frame>
        </axis>
      </joint>
      <link name='yumi_link_5_r'>
        <pose frame=''>0.49055 -0.07866 0.588013 -2.22634 -0.489119 -0.397989</pose>
        <inertial>
          <pose frame=''>0 0 0 0 -0 0</pose>
          <mass>2</mass>
          <inertia>
            <ixx>0.1</ixx>
            <ixy>0</ixy>
            <ixz>0</ixz>
            <iyy>0.1</iyy>
            <iyz>0</iyz>
            <izz>0.1</izz>
          </inertia>
        </inertial>
        <collision name='yumi_link_5_r_collision'>
          <pose frame=''>0 0 0 0 -0 0</pose>
          <geometry>
            <mesh>
              <scale>1 1 1</scale>
              <uri>/home/houlam/yumi_depends_ws/src/yumi/yumi_description/meshes/coarse/link_5.stl</uri>
            </mesh>
          </geometry>
          <max_contacts>10</max_contacts>
          <surface>
            <contact>
              <ode/>
            </contact>
            <bounce/>
            <friction>
              <torsional>
                <ode/>
              </torsional>
              <ode/>
            </friction>
          </surface>
        </collision>
        <visual name='yumi_link_5_r_visual'>
          <pose frame=''>0 0 0 0 -0 0</pose>
          <geometry>
            <mesh>
              <scale>1 1 1</scale>
              <uri>/home/houlam/yumi_depends_ws/src/yumi/yumi_description/meshes/link_5.stl</uri>
            </mesh>
          </geometry>
        </visual>
        <self_collide>0</self_collide>
        <enable_wind>0</enable_wind>
        <kinematic>0</kinematic>
      </link>
      <joint name='yumi_joint_4_r' type='revolute'>
        <child>yumi_link_5_r</child>
        <parent>yumi_link_4_r</parent>
        <axis>
          <xyz>0.571259 0.619754 -0.538116</xyz>
          <limit>
            <lower>-5.06145</lower>
            <upper>5.06145</upper>
            <effort>300</effort>
            <velocity>6.98132</velocity>
          </limit>
          <dynamics>
            <damping>0.5</damping>
            <friction>0</friction>
            <spring_reference>0</spring_reference>
            <spring_stiffness>0</spring_stiffness>
          </dynamics>
          <use_parent_model_frame>1</use_parent_model_frame>
        </axis>
      </joint>
      <link name='yumi_link_6_r'>
        <pose frame=''>0.525927 -0.007205 0.521306 -0.655546 -0.489119 -0.397989</pose>
        <inertial>
          <pose frame=''>0 0 0 0 -0 0</pose>
          <mass>2</mass>
          <inertia>
            <ixx>0.1</ixx>
            <ixy>0</ixy>
            <ixz>0</ixz>
            <iyy>0.1</iyy>
            <iyz>0</iyz>
            <izz>0.1</izz>
          </inertia>
        </inertial>
        <collision name='yumi_link_6_r_collision'>
          <pose frame=''>0 0 0 0 -0 0</pose>
          <geometry>
            <mesh>
              <scale>1 1 1</scale>
              <uri>/home/houlam/yumi_depends_ws/src/yumi/yumi_description/meshes/coarse/link_6.stl</uri>
            </mesh>
          </geometry>
          <max_contacts>10</max_contacts>
          <surface>
            <contact>
              <ode/>
            </contact>
            <bounce/>
            <friction>
              <torsional>
                <ode/>
              </torsional>
              <ode/>
            </friction>
          </surface>
        </collision>
        <visual name='yumi_link_6_r_visual'>
          <pose frame=''>0 0 0 0 -0 0</pose>
          <geometry>
            <mesh>
              <scale>1 1 1</scale>
              <uri>/home/houlam/yumi_depends_ws/src/yumi/yumi_description/meshes/link_6.stl</uri>
            </mesh>
          </geometry>
        </visual>
        <self_collide>0</self_collide>
        <enable_wind>0</enable_wind>
        <kinematic>0</kinematic>
      </link>
      <joint name='yumi_joint_5_r' type='revolute'>
        <child>yumi_link_6_r</child>
        <parent>yumi_link_5_r</parent>
        <axis>
          <xyz>-0.107089 0.706299 0.699767</xyz>
          <limit>
            <lower>-1.53589</lower>
            <upper>2.40855</upper>
            <effort>300</effort>
            <velocity>6.98132</velocity>
          </limit>
          <dynamics>
            <damping>0.5</damping>
            <friction>0</friction>
            <spring_reference>0</spring_reference>
            <spring_stiffness>0</spring_stiffness>
          </dynamics>
          <use_parent_model_frame>1</use_parent_model_frame>
        </axis>
      </joint>
      <link name='yumi_link_7_r'>
        <pose frame=''>0.564465 0.00153 0.518386 -2.22634 -0.489119 -0.397989</pose>
        <inertial>
          <pose frame=''>0 0 0.000636 0 -0 0</pose>
          <mass>2.2</mass>
          <inertia>
            <ixx>0.100109</ixx>
            <ixy>0</ixy>
            <ixz>0</ixz>
            <iyy>0.100109</iyy>
            <iyz>0</iyz>
            <izz>0.1001</izz>
          </inertia>
        </inertial>
        <collision name='yumi_link_7_r_collision'>
          <pose frame=''>0 0 0 0 -0 0</pose>
          <geometry>
            <mesh>
              <scale>1 1 1</scale>
              <uri>/home/houlam/yumi_depends_ws/src/yumi/yumi_description/meshes/coarse/link_7.stl</uri>
            </mesh>
          </geometry>
          <max_contacts>10</max_contacts>
          <surface>
            <contact>
              <ode/>
            </contact>
            <bounce/>
            <friction>
              <torsional>
                <ode/>
              </torsional>
              <ode/>
            </friction>
          </surface>
        </collision>
        <collision name='yumi_link_7_r_fixed_joint_lump__gripper_r_base_collision_1'>
          <pose frame=''>0 0 0.007 0 -0 -3.14159</pose>
          <geometry>
            <mesh>
              <scale>1 1 1</scale>
              <uri>/home/houlam/yumi_depends_ws/src/yumi/yumi_description/meshes/gripper/coarse/base.stl</uri>
            </mesh>
          </geometry>
          <surface>
            <contact>
              <ode/>
            </contact>
            <friction>
              <ode>
                <mu>0.2</mu>
                <mu2>0.2</mu2>
              </ode>
              <torsional>
                <ode/>
              </torsional>
            </friction>
            <bounce/>
          </surface>
          <max_contacts>10</max_contacts>
        </collision>
        <visual name='yumi_link_7_r_visual'>
          <pose frame=''>0 0 0 0 -0 0</pose>
          <geometry>
            <mesh>
              <scale>1 1 1</scale>
              <uri>/home/houlam/yumi_depends_ws/src/yumi/yumi_description/meshes/link_7.stl</uri>
            </mesh>
          </geometry>
        </visual>
        <visual name='yumi_link_7_r_fixed_joint_lump__gripper_r_base_visual_1'>
          <pose frame=''>0 0 0.007 0 -0 -3.14159</pose>
          <geometry>
            <mesh>
              <scale>1 1 1</scale>
              <uri>/home/houlam/yumi_depends_ws/src/yumi/yumi_description/meshes/gripper/base.stl</uri>
            </mesh>
          </geometry>
          <material>
            <script>
              <name>Gazebo/Light_Grey</name>
              <uri>file://media/materials/scripts/gazebo.material</uri>
            </script>
          </material>
        </visual>
        <gravity>1</gravity>
        <velocity_decay/>
        <self_collide>0</self_collide>
        <enable_wind>0</enable_wind>
        <kinematic>0</kinematic>
      </link>
      <joint name='yumi_joint_6_r' type='revolute'>
        <child>yumi_link_7_r</child>
        <parent>yumi_link_6_r</parent>
        <axis>
          <xyz>0.571259 0.619754 -0.538116</xyz>
          <limit>
            <lower>-3.9968</lower>
            <upper>3.9968</upper>
            <effort>300</effort>
            <velocity>6.98132</velocity>
          </limit>
          <dynamics>
            <damping>0.5</damping>
            <friction>0</friction>
            <spring_reference>0</spring_reference>
            <spring_stiffness>0</spring_stiffness>
          </dynamics>
          <use_parent_model_frame>1</use_parent_model_frame>
        </axis>
      </joint>
      <link name='gripper_r_finger_r'>
        <pose frame=''>0.616974 0.053151 0.465031 2.22634 0.489119 2.7436</pose>
        <inertial>
          <pose frame=''>0 0 0 0 -0 0</pose>
          <mass>0.04</mass>
          <inertia>
            <ixx>1.66667e-05</ixx>
            <ixy>0</ixy>
            <ixz>0</ixz>
            <iyy>1.66667e-05</iyy>
            <iyz>0</iyz>
            <izz>1.66667e-05</izz>
          </inertia>
        </inertial>
        <collision name='gripper_r_finger_r_collision'>
          <pose frame=''>0 0 0 0 -0 0</pose>
          <geometry>
            <mesh>
              <scale>1 1 1</scale>
              <uri>/home/houlam/yumi_depends_ws/src/yumi/yumi_description/meshes/gripper/coarse/finger.stl</uri>
            </mesh>
          </geometry>
          <max_contacts>10</max_contacts>
          <surface>
            <contact>
              <ode/>
            </contact>
            <bounce/>
            <friction>
              <torsional>
                <ode/>
              </torsional>
              <ode/>
            </friction>
          </surface>
        </collision>
        <visual name='gripper_r_finger_r_visual'>
          <pose frame=''>0 0 0 0 -0 0</pose>
          <geometry>
            <mesh>
              <scale>1 1 1</scale>
              <uri>/home/houlam/yumi_depends_ws/src/yumi/yumi_description/meshes/gripper/finger.stl</uri>
            </mesh>
          </geometry>
        </visual>
        <self_collide>0</self_collide>
        <enable_wind>0</enable_wind>
        <kinematic>0</kinematic>
      </link>
      <joint name='gripper_r_joint' type='prismatic'>
        <child>gripper_r_finger_r</child>
        <parent>yumi_link_7_r</parent>
        <axis>
          <xyz>0.813754 -0.342122 0.469848</xyz>
          <limit>
            <lower>0</lower>
            <upper>0.025</upper>
            <effort>20</effort>
            <velocity>2</velocity>
          </limit>
          <dynamics>
            <damping>1</damping>
            <friction>0</friction>
            <spring_reference>0</spring_reference>
            <spring_stiffness>0</spring_stiffness>
          </dynamics>
          <use_parent_model_frame>1</use_parent_model_frame>
        </axis>
      </joint>
      <link name='gripper_r_finger_l'>
        <pose frame=''>0.615582 0.062333 0.474128 -2.22634 -0.489119 -0.397989</pose>
        <inertial>
          <pose frame=''>0 0 0 0 -0 0</pose>
          <mass>0.04</mass>
          <inertia>
            <ixx>1.66667e-05</ixx>
            <ixy>0</ixy>
            <ixz>0</ixz>
            <iyy>1.66667e-05</iyy>
            <iyz>0</iyz>
            <izz>1.66667e-05</izz>
          </inertia>
        </inertial>
        <collision name='gripper_r_finger_l_collision'>
          <pose frame=''>0 0 0 0 -0 0</pose>
          <geometry>
            <mesh>
              <scale>1 1 1</scale>
              <uri>/home/houlam/yumi_depends_ws/src/yumi/yumi_description/meshes/gripper/coarse/finger.stl</uri>
            </mesh>
          </geometry>
          <max_contacts>10</max_contacts>
          <surface>
            <contact>
              <ode/>
            </contact>
            <bounce/>
            <friction>
              <torsional>
                <ode/>
              </torsional>
              <ode/>
            </friction>
          </surface>
        </collision>
        <visual name='gripper_r_finger_l_visual'>
          <pose frame=''>0 0 0 0 -0 0</pose>
          <geometry>
            <mesh>
              <scale>1 1 1</scale>
              <uri>/home/houlam/yumi_depends_ws/src/yumi/yumi_description/meshes/gripper/finger.stl</uri>
            </mesh>
          </geometry>
        </visual>
        <self_collide>0</self_collide>
        <enable_wind>0</enable_wind>
        <kinematic>0</kinematic>
      </link>
      <joint name='gripper_r_joint_m' type='prismatic'>
        <child>gripper_r_finger_l</child>
        <parent>yumi_link_7_r</parent>
        <axis>
          <xyz>-0.813754 0.342122 -0.469848</xyz>
          <limit>
            <lower>0</lower>
            <upper>0.025</upper>
            <effort>20</effort>
            <velocity>2</velocity>
          </limit>
          <dynamics>
            <damping>1</damping>
            <friction>0</friction>
            <spring_reference>0</spring_reference>
            <spring_stiffness>0</spring_stiffness>
          </dynamics>
          <use_parent_model_frame>1</use_parent_model_frame>
        </axis>
      </joint>
      <plugin name='gazebo_ros_controller' filename='libgazebo_ros_control.so'>
        <robotNamespace>/yumi</robotNamespace>
        <legacyModeNS>1</legacyModeNS>
      </plugin>
      <plugin name='mimic_plugin' filename='libgazebo_mimic_plugin.so'>
        <joint>gripper_r_joint</joint>
        <mimicJoint>gripper_r_joint_m</mimicJoint>
        <multiplier>1.0</multiplier>
        <robotNamespace>/</robotNamespace>
      </plugin>
      <plugin name='mimic_plugin' filename='libgazebo_mimic_plugin.so'>
        <joint>gripper_l_joint</joint>
        <mimicJoint>gripper_l_joint_m</mimicJoint>
        <multiplier>1.0</multiplier>
        <robotNamespace>/</robotNamespace>
      </plugin>
      <static>0</static>
      <plugin name='camera' filename='librealsense_gazebo_plugin.so'>
        <prefix>camera</prefix>
        <depthUpdateRate>30.0</depthUpdateRate>
        <colorUpdateRate>30.0</colorUpdateRate>
        <infraredUpdateRate>30.0</infraredUpdateRate>
        <depthTopicName>depth/image_raw</depthTopicName>
        <depthCameraInfoTopicName>depth/camera_info</depthCameraInfoTopicName>
        <colorTopicName>color/image_raw</colorTopicName>
        <colorCameraInfoTopicName>color/camera_info</colorCameraInfoTopicName>
        <infrared1TopicName>infra1/image_raw</infrared1TopicName>
        <infrared1CameraInfoTopicName>infra1/camera_info</infrared1CameraInfoTopicName>
        <infrared2TopicName>infra2/image_raw</infrared2TopicName>
        <infrared2CameraInfoTopicName>infra2/camera_info</infrared2CameraInfoTopicName>
        <colorOpticalframeName>camera_color_optical_frame</colorOpticalframeName>
        <depthOpticalframeName>camera_depth_optical_frame</depthOpticalframeName>
        <infrared1OpticalframeName>camera_left_ir_optical_frame</infrared1OpticalframeName>
        <infrared2OpticalframeName>camera_right_ir_optical_frame</infrared2OpticalframeName>
        <rangeMinDepth>0.2</rangeMinDepth>
        <rangeMaxDepth>10.0</rangeMaxDepth>
        <pointCloud>1</pointCloud>
        <pointCloudTopicName>depth/color/points</pointCloudTopicName>
        <pointCloudCutoff>0.25</pointCloudCutoff>
        <pointCloudCutoffMax>9.0</pointCloudCutoffMax>
        <robotNamespace>/</robotNamespace>
      </plugin>
      <pose frame=''>0 0 0 0 -0 0</pose>
    </model>
    <state world_name='default'>
      <sim_time>118 494000000</sim_time>
      <real_time>120 313952341</real_time>
      <wall_time>1618978193 187450500</wall_time>
      <iterations>118494</iterations>
      <model name='coke_can2_0'>
        <pose frame=''>0.35262 0.059734 -0.132562 -0.01771 0.019797 -0.313278</pose>
        <scale>1 1 1</scale>
        <link name='link'>
          <pose frame=''>0.35262 0.059734 -0.132562 -0.01771 0.019797 -0.313278</pose>
          <velocity>0.016499 0.049193 0.001048 0.354865 -0.119334 0.01506</velocity>
          <acceleration>0.166412 -0.107435 0.003396 -0.780612 -1.20695 -0.128431</acceleration>
          <wrench>0.001664 -0.001074 3.4e-05 0 -0 0</wrench>
        </link>
      </model>
      <model name='ground_plane'>
        <pose frame=''>0 0 0 0 -0 0</pose>
        <scale>1 1 1</scale>
        <link name='link'>
          <pose frame=''>0 0 0 0 -0 0</pose>
          <velocity>0 0 0 0 -0 0</velocity>
          <acceleration>0 0 0 0 -0 0</acceleration>
          <wrench>0 0 0 0 -0 0</wrench>
        </link>
      </model>
      <model name='unit_box'>
        <pose frame=''>0.325845 -0.132316 0.028909 1.4e-05 -5e-06 -1.7e-05</pose>
        <scale>0.104981 0.025301 0.057815</scale>
        <link name='link'>
          <pose frame=''>0.325845 -0.132316 0.028909 1.4e-05 -5e-06 -1.7e-05</pose>
          <velocity>0 0 0 0 -0 0</velocity>
          <acceleration>0.087268 -0.021034 -0.167628 -2.41409 0.123267 -3.14159</acceleration>
          <wrench>0.087268 -0.021034 -0.167628 0 -0 0</wrench>
        </link>
      </model>
      <model name='unit_cylinder'>
        <pose frame=''>0.393414 -0.033931 0.021108 0 -0 1e-06</pose>
        <scale>1 1 1</scale>
        <link name='link'>
          <pose frame=''>0.393414 -0.033931 0.021108 0 -0 1e-06</pose>
          <velocity>0 0 0 0 -0 0</velocity>
          <acceleration>0 0 -9.8 0 -0 0</acceleration>
          <wrench>0 0 -9.8 0 -0 0</wrench>
        </link>
      </model>
      <model name='yumi'>
        <pose frame=''>0 -0 0 0 -0 0</pose>
        <scale>1 1 1</scale>
        <link name='gripper_l_finger_l'>
          <pose frame=''>0.474511 0.31332 0.286135 1.75601 0.963824 1.77259</pose>
          <velocity>-0.000939 0.004256 -0.006777 -0.000642 0.000473 -2.4e-05</velocity>
          <acceleration>-0.939462 4.25552 -6.7769 -0.642086 0.472688 -0.02366</acceleration>
          <wrench>-0.037578 0.170221 -0.271076 0 -0 0</wrench>
        </link>
        <link name='gripper_l_finger_r'>
          <pose frame=''>0.469038 0.352019 0.252361 -1.75604 -0.963831 -1.36897</pose>
          <velocity>-4.5e-05 -0.000213 -0.000262 -0.000642 0.000502 -7e-06</velocity>
          <acceleration>0.01489 0.018915 -0.056474 -0.015233 0.137021 0.035772</acceleration>
          <wrench>0.000596 0.000757 -0.002259 0 -0 0</wrench>
        </link>
        <link name='gripper_r_finger_l'>
          <pose frame=''>0.475509 -0.322616 0.293203 -1.75468 0.967344 -1.76975</pose>
          <velocity>-0.001009 -0.004316 -0.006753 0.000657 0.000968 -0.00037</velocity>
          <acceleration>-1.00893 -4.31565 -6.75311 0.65727 0.967847 -0.370186</acceleration>
          <wrench>-0.040357 -0.172626 -0.270125 0 -0 0</wrench>
        </link>
        <link name='gripper_r_finger_r'>
          <pose frame=''>0.469651 -0.339642 0.244785 1.75471 -0.96735 1.3718</pose>
          <velocity>-0.000116 0.000406 0.000181 0.000627 0.00119 -0.00052</velocity>
          <acceleration>-0.005787 -0.095561 -0.158596 -0.040436 0.063228 0.001515</acceleration>
          <wrench>-0.000231 -0.003822 -0.006344 0 -0 0</wrench>
        </link>
        <link name='yumi_base_link'>
          <pose frame=''>0 0 0.1 0 -0 0</pose>
          <velocity>3e-06 1e-06 5e-06 -1.4e-05 3.1e-05 -1e-06</velocity>
          <acceleration>0.005908 0.000313 0.011529 -0.008762 0.064386 -0.002855</acceleration>
          <wrench>0.08862 0.004696 0.172934 0 -0 0</wrench>
        </link>
        <link name='yumi_link_1_l'>
          <pose frame=''>0.05355 0.072499 0.514919 0.943177 0.643433 1.5581</pose>
          <velocity>1.8e-05 1.2e-05 1e-06 -0.000296 -7.2e-05 -0.000157</velocity>
          <acceleration>0.042788 0.010132 -0.006208 -0.017694 0.093686 -0.001136</acceleration>
          <wrench>0.085576 0.020265 -0.012416 0 -0 0</wrench>
        </link>
        <link name='yumi_link_1_r'>
          <pose frame=''>0.05355 -0.0725 0.51492 -0.941311 0.646707 -1.55523</pose>
          <velocity>1.7e-05 8e-06 5e-06 -3.6e-05 4.4e-05 -9e-06</velocity>
          <acceleration>0.041436 0.006458 0.002122 -0.01112 0.079511 0.00074</acceleration>
          <wrench>0.082872 0.012916 0.004244 0 -0 0</wrench>
        </link>
        <link name='yumi_link_2_l'>
          <pose frame=''>0.135239 0.130698 0.543901 -2.27993 0.105219 -2.36434</pose>
          <velocity>2.5e-05 8e-06 -1.1e-05 -0.000514 0.000115 8.7e-05</velocity>
          <acceleration>0.042462 0.0108 -0.004341 -0.015622 0.096788 -9.2e-05</acceleration>
          <wrench>0.084924 0.021599 -0.008682 0 -0 0</wrench>
        </link>
        <link name='yumi_link_2_r'>
          <pose frame=''>0.135299 -0.130651 0.543827 -0.865045 0.103941 2.36573</pose>
          <velocity>1.8e-05 9e-06 4e-06 0.000231 0.000279 -0.000312</velocity>
          <acceleration>0.039585 0.006483 0.002866 -0.017169 0.085351 -0.001125</acceleration>
          <wrench>0.079171 0.012967 0.005733 0 -0 0</wrench>
        </link>
        <link name='yumi_link_3_l'>
          <pose frame=''>0.087398 0.241508 0.416612 2.5027 -0.347668 -2.91617</pose>
          <velocity>2e-06 -6.1e-05 -6.3e-05 -0.000646 0.000287 -0.000159</velocity>
          <acceleration>0.032089 0.009699 -0.002382 -0.015212 0.10094 0.003066</acceleration>
          <wrench>0.064178 0.019398 -0.004764 0 -0 0</wrench>
        </link>
        <link name='yumi_link_3_r'>
          <pose frame=''>0.087833 -0.241124 0.416105 -2.50646 -0.346991 2.91919</pose>
          <velocity>-5.2e-05 5.4e-05 -7e-06 0.00039 0.000497 -2e-06</velocity>
          <acceleration>0.029986 0.004603 0.009957 -0.024533 0.0912 -0.002414</acceleration>
          <wrench>0.059971 0.009205 0.019914 0 -0 0</wrench>
        </link>
        <link name='yumi_link_4_l'>
          <pose frame=''>0.094294 0.291256 0.342923 -2.95639 0.963827 1.77259</pose>
          <velocity>-1.1e-05 -0.000109 -9.7e-05 -0.000642 0.000465 -3.8e-05</velocity>
          <acceleration>0.025695 0.009088 -0.004232 -0.015325 0.104329 0.005976</acceleration>
          <wrench>0.05139 0.018176 -0.008463 0 -0 0</wrench>
        </link>
        <link name='yumi_link_4_r'>
          <pose frame=''>0.094923 -0.290615 0.342262 -0.183868 0.967346 -1.76975</pose>
          <velocity>-8.9e-05 8.3e-05 -2.9e-05 0.000379 0.000793 -0.000201</velocity>
          <acceleration>0.023692 0.002889 0.011479 -0.029506 0.09643 -0.004705</acceleration>
          <wrench>0.047383 0.005777 0.022959 0 -0 0</wrench>
        </link>
        <link name='yumi_link_5_l'>
          <pose frame=''>0.253166 0.321923 0.292368 1.756 0.963827 1.77259</pose>
          <velocity>-3.3e-05 -0.000147 -0.00019 -0.00066 0.000465 -3.5e-05</velocity>
          <acceleration>0.020987 0.008968 -0.020436 -0.015544 0.106195 0.007239</acceleration>
          <wrench>0.041974 0.017936 -0.040871 0 -0 0</wrench>
        </link>
        <link name='yumi_link_5_r'>
          <pose frame=''>0.253921 -0.320839 0.291834 -1.75467 0.967348 -1.76976</pose>
          <velocity>-0.000135 7.1e-05 -0.000166 0.000562 0.000786 -0.000223</velocity>
          <acceleration>0.018885 0.000429 -0.002456 -0.033112 0.10099 -0.007733</acceleration>
          <wrench>0.03777 0.000858 -0.004912 0 -0 0</wrench>
        </link>
        <link name='yumi_link_6_l'>
          <pose frame=''>0.355967 0.311736 0.304001 -2.95639 0.963828 1.77259</pose>
          <velocity>-2.8e-05 -0.000143 -0.000231 -0.00066 0.000474 -2.9e-05</velocity>
          <acceleration>0.022213 0.00979 -0.0309 -0.015528 0.106382 0.007354</acceleration>
          <wrench>0.044426 0.01958 -0.0618 0 -0 0</wrench>
        </link>
        <link name='yumi_link_6_r'>
          <pose frame=''>0.356687 -0.310512 0.30365 -0.183874 0.967348 -1.76975</pose>
          <velocity>-0.000124 4.1e-05 -0.000241 0.000555 0.000977 -0.000351</velocity>
          <acceleration>0.020305 -0.00021 -0.013125 -0.035725 0.104863 -0.009678</acceleration>
          <wrench>0.040609 -0.00042 -0.026249 0 -0 0</wrench>
        </link>
        <link name='yumi_link_7_l'>
          <pose frame=''>0.381686 0.328239 0.278778 1.756 0.963828 1.77259</pose>
          <velocity>-3.9e-05 -0.000161 -0.000254 -0.000641 0.000474 -3.1e-05</velocity>
          <acceleration>0.019401 0.009419 -0.033744 -0.015348 0.105645 0.007152</acceleration>
          <wrench>0.042683 0.020721 -0.074237 0 -0 0</wrench>
        </link>
        <link name='yumi_link_7_r'>
          <pose frame=''>0.38247 -0.326887 0.278408 -1.75467 0.967348 -1.76976</pose>
          <velocity>-0.000154 4.6e-05 -0.000275 0.000657 0.000973 -0.000363</velocity>
          <acceleration>0.017496 -0.001585 -0.015278 -0.037724 0.108028 -0.011044</acceleration>
          <wrench>0.03849 -0.003487 -0.033612 0 -0 0</wrench>
        </link>
      </model>
      <light name='sun'>
        <pose frame=''>0 0 10 0 -0 0</pose>
      </light>
    </state>
    <model name='unit_box'>
      <pose frame=''>1.63172 -0.671167 0.5 0 -0 0</pose>
      <link name='link'>
        <inertial>
          <mass>1</mass>
          <inertia>
            <ixx>0.166667</ixx>
            <ixy>0</ixy>
            <ixz>0</ixz>
            <iyy>0.166667</iyy>
            <iyz>0</iyz>
            <izz>0.166667</izz>
          </inertia>
          <pose frame=''>0 0 0 0 -0 0</pose>
        </inertial>
        <collision name='collision'>
          <geometry>
            <box>
              <size>9.52557 39.5249 17.2965</size>
            </box>
          </geometry>
          <max_contacts>10</max_contacts>
          <surface>
            <contact>
              <ode/>
            </contact>
            <bounce/>
            <friction>
              <torsional>
                <ode/>
              </torsional>
              <ode/>
            </friction>
          </surface>
        </collision>
        <visual name='visual'>
          <geometry>
            <box>
              <size>9.52557 39.5249 17.2965</size>
            </box>
          </geometry>
          <material>
            <script>
              <name>Gazebo/Grey</name>
              <uri>file://media/materials/scripts/gazebo.material</uri>
            </script>
          </material>
        </visual>
        <self_collide>0</self_collide>
        <enable_wind>0</enable_wind>
        <kinematic>0</kinematic>
      </link>
    </model>
    <model name='unit_cylinder'>
      <link name='link'>
        <inertial>
          <mass>1</mass>
          <inertia>
            <ixx>0.145833</ixx>
            <ixy>0</ixy>
            <ixz>0</ixz>
            <iyy>0.145833</iyy>
            <iyz>0</iyz>
            <izz>0.125</izz>
          </inertia>
          <pose frame=''>0 0 0 0 -0 0</pose>
        </inertial>
        <self_collide>0</self_collide>
        <enable_wind>0</enable_wind>
        <kinematic>0</kinematic>
        <pose frame=''>0 0 0 0 -0 0</pose>
        <gravity>1</gravity>
        <visual name='visual'>
          <geometry>
            <cylinder>
              <radius>0.0526959</radius>
              <length>0.0422172</length>
            </cylinder>
          </geometry>
          <material>
            <script>
              <name>Gazebo/Green</name>
              <uri>file://media/materials/scripts/gazebo.material</uri>
            </script>
            <shader type='pixel'>
              <normal_map>__default__</normal_map>
            </shader>
            <ambient>0.3 0.3 0.3 1</ambient>
            <diffuse>0.7 0.7 0.7 1</diffuse>
            <specular>0.01 0.01 0.01 1</specular>
            <emissive>0 0 0 1</emissive>
          </material>
          <pose frame=''>0 0 0 0 -0 0</pose>
          <transparency>0</transparency>
          <cast_shadows>1</cast_shadows>
        </visual>
        <collision name='collision'>
          <laser_retro>0</laser_retro>
          <max_contacts>10</max_contacts>
          <pose frame=''>0 0 0 0 -0 0</pose>
          <geometry>
            <cylinder>
              <radius>0.052696</radius>
              <length>0.042217</length>
            </cylinder>
          </geometry>
          <surface>
            <friction>
              <ode>
                <mu>1</mu>
                <mu2>1</mu2>
                <fdir1>0 0 0</fdir1>
                <slip1>0</slip1>
                <slip2>0</slip2>
              </ode>
              <torsional>
                <coefficient>1</coefficient>
                <patch_radius>0</patch_radius>
                <surface_radius>0</surface_radius>
                <use_patch_radius>1</use_patch_radius>
                <ode>
                  <slip>0</slip>
                </ode>
              </torsional>
            </friction>
            <bounce>
              <restitution_coefficient>0</restitution_coefficient>
              <threshold>1e+06</threshold>
            </bounce>
            <contact>
              <collide_without_contact>0</collide_without_contact>
              <collide_without_contact_bitmask>1</collide_without_contact_bitmask>
              <collide_bitmask>1</collide_bitmask>
              <ode>
                <soft_cfm>0</soft_cfm>
                <soft_erp>0.2</soft_erp>
                <kp>1e+13</kp>
                <kd>1</kd>
                <max_vel>0.01</max_vel>
                <min_depth>0</min_depth>
              </ode>
              <bullet>
                <split_impulse>1</split_impulse>
                <split_impulse_penetration_threshold>-0.01</split_impulse_penetration_threshold>
                <soft_cfm>0</soft_cfm>
                <soft_erp>0.2</soft_erp>
                <kp>1e+13</kp>
                <kd>1</kd>
              </bullet>
            </contact>
          </surface>
        </collision>
      </link>
      <static>0</static>
      <allow_auto_disable>1</allow_auto_disable>
      <pose frame=''>1.35667 -1.87369 0.021109 0 -0 0</pose>
    </model>
    <model name='coke_can2_0'>
      <link name='link'>
        <inertial>
          <pose frame=''>0 0 0 0 -0 0</pose>
          <mass>0.01</mass>
          <inertia>
            <ixx>0.00058</ixx>
            <ixy>0</ixy>
            <ixz>0</ixz>
            <iyy>0.00058</iyy>
            <iyz>0</iyz>
            <izz>0.00019</izz>
          </inertia>
        </inertial>
        <self_collide>0</self_collide>
        <enable_wind>0</enable_wind>
        <kinematic>0</kinematic>
        <pose frame=''>0 0 0 0 -0 0</pose>
        <gravity>1</gravity>
        <visual name='ModelPreview_17::link::visual_1'>
          <pose frame=''>0 0 0 0 -0 0</pose>
          <geometry>
            <mesh>
              <uri>model://coke_can/meshes/coke_can.dae</uri>
              <scale>0.3 0.3 0.3</scale>
            </mesh>
          </geometry>
          <material>
            <shader type='pixel'>
              <normal_map>__default__</normal_map>
            </shader>
            <script>
              <name>ModelPreview_17::link::visual_1_MATERIAL_</name>
              <uri>__default__</uri>
            </script>
            <ambient>0 0 0 1</ambient>
            <diffuse>0 0 0 1</diffuse>
            <specular>0 0 0 1</specular>
            <emissive>0 0 0 1</emissive>
          </material>
          <transparency>0</transparency>
          <cast_shadows>1</cast_shadows>
        </visual>
        <collision name='collision_1'>
          <laser_retro>0</laser_retro>
          <max_contacts>10</max_contacts>
          <pose frame=''>0 0 0 0 -0 0</pose>
          <geometry>
            <mesh>
              <uri>/home/houlam/.gazebo/models/coke_can/meshes/coke_can.dae</uri>
              <scale>0.3 0.3 0.3</scale>
            </mesh>
          </geometry>
          <surface>
            <friction>
              <ode>
                <mu>1</mu>
                <mu2>1</mu2>
                <fdir1>0 0 0</fdir1>
                <slip1>0</slip1>
                <slip2>0</slip2>
              </ode>
              <torsional>
                <coefficient>1</coefficient>
                <patch_radius>0</patch_radius>
                <surface_radius>0</surface_radius>
                <use_patch_radius>1</use_patch_radius>
                <ode>
                  <slip>0</slip>
                </ode>
              </torsional>
            </friction>
            <bounce>
              <restitution_coefficient>0</restitution_coefficient>
              <threshold>1e+06</threshold>
            </bounce>
            <contact>
              <collide_without_contact>0</collide_without_contact>
              <collide_without_contact_bitmask>1</collide_without_contact_bitmask>
              <collide_bitmask>1</collide_bitmask>
              <ode>
                <soft_cfm>0</soft_cfm>
                <soft_erp>0.2</soft_erp>
                <kp>1e+13</kp>
                <kd>1</kd>
                <max_vel>0.01</max_vel>
                <min_depth>0</min_depth>
              </ode>
              <bullet>
                <split_impulse>1</split_impulse>
                <split_impulse_penetration_threshold>-0.01</split_impulse_penetration_threshold>
                <soft_cfm>0</soft_cfm>
                <soft_erp>0.2</soft_erp>
                <kp>1e+13</kp>
                <kd>1</kd>
              </bullet>
            </contact>
          </surface>
        </collision>
      </link>
      <static>0</static>
      <allow_auto_disable>1</allow_auto_disable>
      <pose frame=''>1.16604 -1.1518 -0.138471 0.03304 -0.034445 -0.296786</pose>
    </model>
    <gui fullscreen='0'>
      <camera name='user_camera'>
        <pose frame=''>0.819594 2.89609 0.896426 0 0.12037 -1.8493</pose>
        <view_controller>orbit</view_controller>
        <projection_type>perspective</projection_type>
      </camera>
    </gui>
  </world>
</sdf>
